<?xml version="1.0"?>
<robot name="robot2025" xmlns:xacro="http://ros.org/wiki/xacro">

    <!-- Materials -->
    <material name="orange">
        <color rgba="1.0 0.45 0.0 1" />
    </material>
    <material name="blue">
        <color rgba="0.0 0.0 1.0 1" />
    </material>

    <!-- Base link -->
    <link name="base_link">
        <visual>
            <geometry>
                <box size="0.4 0.3 0.2" />
            </geometry>
            <material name="orange" />
        </visual>
        <collision>
            <geometry>
                <box size="0.4 0.3 0.2" />
            </geometry>
        </collision>
        <inertial>
            <mass value="5.0" />
            <inertia ixx="0.1" ixy="0.0" ixz="0.0" iyy="0.1" iyz="0.0" izz="0.1" />
        </inertial>
    </link>

    <!-- Left wheel -->
    <link name="left_wheel">
        <visual>
            <geometry>
                <cylinder radius="0.05" length="0.02" />
            </geometry>
            <origin xyz="0 0 0" rpy="1.5708 0 0" />
        </visual>
        <collision>
            <geometry>
                <cylinder radius="0.05" length="0.02" />
            </geometry>
            <origin xyz="0 0 0" rpy="1.5708 0 0" />
        </collision>
        <inertial>
            <mass value="0.2" />
            <inertia ixx="0.001" ixy="0" ixz="0" iyy="0.001" iyz="0" izz="0.001" />
        </inertial>
    </link>

    <joint name="left_wheel_joint" type="continuous">
        <parent link="base_link" />
        <child link="left_wheel" />
        <origin xyz="0 0.15 -0.07" rpy="0 0 0" />
        <axis xyz="0 1 0" />
    </joint>

    <transmission name="left_wheel_trans">
        <type>transmission_interface/SimpleTransmission</type>
        <joint name="left_wheel_joint">
            <hardwareInterface>hardware_interface/VelocityJointInterface</hardwareInterface>
        </joint>
        <actuator name="left_wheel_motor">
            <mechanicalReduction>1</mechanicalReduction>
        </actuator>
    </transmission>

    <!-- Right wheel -->
    <link name="right_wheel">
        <visual>
            <geometry>
                <cylinder radius="0.05" length="0.02" />
            </geometry>
            <origin xyz="0 0 0" rpy="1.5708 0 0" />
        </visual>
        <collision>
            <geometry>
                <cylinder radius="0.05" length="0.02" />
            </geometry>
            <origin xyz="0 0 0" rpy="1.5708 0 0" />
        </collision>
        <inertial>
            <mass value="0.2" />
            <inertia ixx="0.001" ixy="0" ixz="0" iyy="0.001" iyz="0" izz="0.001" />
        </inertial>
    </link>

    <joint name="right_wheel_joint" type="continuous">
        <parent link="base_link" />
        <child link="right_wheel" />
        <origin xyz="0 -0.15 -0.07" rpy="0 0 0" />
        <axis xyz="0 1 0" />
    </joint>


    <transmission name="right_wheel_trans">
        <type>transmission_interface/SimpleTransmission</type>
        <joint name="right_wheel_joint">
            <hardwareInterface>hardware_interface/VelocityJointInterface</hardwareInterface>
        </joint>
        <actuator name="right_wheel_motor">
            <mechanicalReduction>1</mechanicalReduction>
        </actuator>
    </transmission>

    <!-- Lidar -->
    <link name="lidar_link">
        <visual>
            <geometry>
                <cylinder radius="0.05" length="0.05" />
            </geometry>
            <origin xyz="0 0 0" rpy="0 0 0" />
            <material name="blue" />
        </visual>
    </link>

    <joint name="lidar_joint" type="fixed">
        <parent link="base_link" />
        <child link="lidar_link" />
        <origin xyz="0 0 0.14" rpy="0 0 0" />
    </joint>

    <!-- IMU -->
    <link name="imu_link" />
    <joint name="imu_joint" type="fixed">
        <parent link="base_link" />
        <child link="imu_link" />
        <origin xyz="0 0 0.1" rpy="0 0 0" />
    </joint>

    <!-- ros2_control config for wheels -->
    <ros2_control name="diff_drive_base" type="system">
        <hardware>
            <plugin>gz_ros2_control/GazeboSystem</plugin>
        </hardware>
        <joint name="left_wheel_joint">
            <command_interface name="velocity" />
            <state_interface name="velocity" />
            <state_interface name="position" />
        </joint>
        <joint name="right_wheel_joint">
            <command_interface name="velocity" />
            <state_interface name="velocity" />
            <state_interface name="position" />
        </joint>
    </ros2_control>

    <!-- Ignition Gazebo diff drive plugin -->
    <gazebo>
        <plugin
            filename="libignition-gazebo-diff-drive-system.so"
            name="ignition::gazebo::systems::DiffDrive">
            <left_joint>left_wheel_joint</left_joint>
            <right_joint>right_wheel_joint</right_joint>
            <wheel_separation>0.3</wheel_separation>
            <wheel_radius>0.05</wheel_radius>
            <odom_publish_frequency>30</odom_publish_frequency>
            <max_linear_acceleration>1</max_linear_acceleration>
            <min_linear_acceleration>-1</min_linear_acceleration>
            <max_angular_acceleration>2</max_angular_acceleration>
            <min_angular_acceleration>-2</min_angular_acceleration>
            <max_linear_velocity>0.5</max_linear_velocity>
            <min_linear_velocity>-0.5</min_linear_velocity>
            <max_angular_velocity>1</max_angular_velocity>
            <min_angular_velocity>-1</min_angular_velocity>
            <topic>diff_drive_base/cmd_vel_unstamped</topic>
            <odom_topic>odom</odom_topic>
            <frame_id>odom</frame_id>
            <child_frame_id>base_link</child_frame_id>
        </plugin>
    </gazebo>

    <ros2_control name="GazeboSystem" type="system">
        <hardware>
          <plugin>gz_ros2_control/GazeboSimSystem</plugin>
        </hardware>
      
        <joint name="left_wheel_joint">
          <command_interface name="velocity"/>
          <state_interface name="velocity"/>
          <state_interface name="position"/>
        </joint>
      
        <joint name="right_wheel_joint">
          <command_interface name="velocity"/>
          <state_interface name="velocity"/>
          <state_interface name="position"/>
        </joint>
      </ros2_control>
      


    <!-- Gazebo sensor definitions -->
    <gazebo reference="lidar_link">
        <sensor name="lidar" type="gpu_lidar">
            <always_on>true</always_on>
            <update_rate>10</update_rate>
            <ray>
                <scan>
                    <horizontal>
                        <samples>360</samples>
                        <resolution>1</resolution>
                        <min_angle>-3.1415</min_angle>
                        <max_angle>3.1415</max_angle>
                    </horizontal>
                </scan>
                <range>
                    <min>0.12</min>
                    <max>10.0</max>
                    <resolution>0.01</resolution>
                </range>
            </ray>
        </sensor>
    </gazebo>

    <gazebo reference="imu_link">
        <sensor name="imu" type="imu">
            <always_on>true</always_on>
            <update_rate>50</update_rate>
        </sensor>
    </gazebo>

</robot>